# Goxel 0.15.1
# One line per voxel
# X Y Z RRGGBB
-1 -8 2 ff4700
-1 -7 2 ff4700
-1 -3 2 ff4700
-1 -2 2 ff4700
-2 -9 3 ff0000
-1 -9 3 ff0000
-2 -8 3 ff0000
-1 -8 3 ff0000
-2 -7 3 ff0000
-1 -7 3 ff0000
-2 -6 3 ff0000
-1 -6 3 ff0000
-1 -5 3 363636
-2 -4 3 ff0000
-1 -4 3 ff0000
-2 -3 3 ff0000
-1 -3 3 ff0000
-2 -2 3 ff0000
-1 -2 3 ff0000
-1 -1 3 ff0000
-2 -9 4 ff0000
-1 -9 4 ff0000
-2 -8 4 ff0000
-1 -8 4 ff0000
-2 -7 4 ff0000
-1 -7 4 ff0000
-2 -6 4 ff0000
-1 -6 4 ff0000
-1 -5 4 363636
-2 -4 4 ff0000
-1 -4 4 ff0000
-2 -3 4 ff0000
-1 -3 4 ff0000
-2 -2 4 ff0000
-1 -2 4 ff0000
-1 -1 4 ff0000
-2 -9 5 ff0000
-1 -9 5 ff0000
-2 -8 5 ff0000
-1 -8 5 ff0000
-2 -7 5 ff0000
-1 -7 5 ff0000
-2 -6 5 ff0000
-1 -6 5 ff0000
-2 -4 5 ff0000
-1 -4 5 ff0000
-2 -3 5 ff0000
-1 -3 5 ff0000
-2 -2 5 ff0000
-1 -2 5 ff0000
-1 -1 5 ff0000
-1 -8 6 ff4700
-1 -7 6 ff4700
-1 -3 6 ff4700
-1 -2 6 ff4700
0 -8 2 ff4700
0 -7 2 ff4700
0 -3 2 ff4700
1 -3 2 ff4700
0 -2 2 ff4700
1 -2 2 ff4700
2 -2 2 ff4700
0 -1 2 ff4700
1 -1 2 ff4700
2 -1 2 ff4700
3 -1 2 ff4700
0 -9 3 ff0000
1 -9 3 ff0000
0 -8 3 ff0000
1 -8 3 ff0000
0 -7 3 ff0000
1 -7 3 ff0000
0 -6 3 ff0000
1 -6 3 ff0000
0 -5 3 363636
0 -4 3 ff0000
1 -4 3 ff0000
0 -3 3 ff0000
1 -3 3 ff0000
2 -3 3 ff0000
0 -2 3 ff0000
1 -2 3 ff0000
2 -2 3 ff0000
3 -2 3 ff0000
0 -1 3 ff0000
1 -1 3 ff0000
2 -1 3 ff0000
3 -1 3 ff0000
4 -1 3 ff0000
0 -9 4 ff0000
1 -9 4 ff0000
0 -8 4 ff0000
1 -8 4 ff0000
0 -7 4 ff0000
1 -7 4 ff0000
0 -6 4 ff0000
1 -6 4 ff0000
0 -5 4 363636
0 -4 4 ff0000
1 -4 4 ff0000
0 -3 4 ff0000
1 -3 4 ff0000
2 -3 4 ff0000
0 -2 4 ff0000
1 -2 4 ff0000
2 -2 4 ff0000
3 -2 4 ff0000
0 -1 4 ff0000
1 -1 4 ff0000
2 -1 4 ff0000
3 -1 4 ff0000
4 -1 4 ff0000
0 -9 5 ff0000
1 -9 5 ff0000
0 -8 5 ff0000
1 -8 5 ff0000
0 -7 5 ff0000
1 -7 5 ff0000
0 -6 5 ff0000
1 -6 5 ff0000
0 -4 5 ff0000
1 -4 5 ff0000
0 -3 5 ff0000
1 -3 5 ff0000
2 -3 5 ff0000
0 -2 5 ff0000
1 -2 5 ff0000
2 -2 5 ff0000
3 -2 5 ff0000
0 -1 5 ff0000
1 -1 5 ff0000
2 -1 5 ff0000
3 -1 5 ff0000
4 -1 5 ff0000
0 -8 6 ff4700
0 -7 6 ff4700
0 -3 6 ff4700
1 -3 6 ff4700
0 -2 6 ff4700
1 -2 6 ff4700
2 -2 6 ff4700
0 -1 6 ff4700
1 -1 6 ff4700
2 -1 6 ff4700
3 -1 6 ff4700
-6 2 2 ff4700
-5 2 2 ff4700
-4 2 2 ff4700
-6 3 2 ff4700
-5 3 2 ff4700
-4 3 2 ff4700
-6 4 2 ff4700
-5 4 2 ff4700
-4 4 2 ff4700
-3 4 2 ff4700
-6 5 2 ff4700
-5 5 2 ff4700
-4 5 2 ff4700
-3 5 2 ff4700
-2 5 2 ff4700
-5 6 2 ff4700
-4 6 2 ff4700
-3 6 2 ff4700
-2 6 2 ff4700
-1 6 2 ff4700
-4 7 2 ff4700
-3 7 2 ff4700
-2 7 2 ff4700
-1 7 2 ff4700
-6 1 3 ff0000
-5 1 3 ff0000
-4 1 3 ff0000
-7 2 3 ff0000
-6 2 3 ff0000
-5 2 3 ff0000
-4 2 3 ff0000
-3 2 3 ff0000
-7 3 3 ff0000
-6 3 3 ff0000
-5 3 3 ff0000
-4 3 3 ff0000
-3 3 3 ff0000
-7 4 3 ff0000
-6 4 3 ff0000
-5 4 3 ff0000
-4 4 3 ff0000
-3 4 3 ff0000
-2 4 3 ff0000
-7 5 3 ff0000
-6 5 3 ff0000
-5 5 3 ff0000
-4 5 3 ff0000
-3 5 3 ff0000
-2 5 3 ff0000
-1 5 3 ff0000
-6 6 3 ff0000
-5 6 3 ff0000
-4 6 3 ff0000
-3 6 3 ff0000
-2 6 3 ff0000
-1 6 3 ff0000
-5 7 3 ff0000
-4 7 3 ff0000
-3 7 3 ff0000
-2 7 3 ff0000
-1 7 3 ff0000
-4 8 3 ff0000
-3 8 3 ff0000
-2 8 3 ff0000
-1 8 3 ff0000
-6 1 4 ff0000
-5 1 4 ff0000
-4 1 4 ff0000
-7 2 4 ff0000
-6 2 4 ff0000
-5 2 4 ff0000
-4 2 4 ff0000
-3 2 4 ff0000
-7 3 4 ff0000
-6 3 4 ff0000
-5 3 4 ff0000
-4 3 4 ff0000
-3 3 4 ff0000
-7 4 4 ff0000
-6 4 4 ff0000
-5 4 4 ff0000
-4 4 4 ff0000
-3 4 4 ff0000
-2 4 4 ff0000
-7 5 4 ff0000
-6 5 4 ff0000
-5 5 4 ff0000
-4 5 4 ff0000
-3 5 4 ff0000
-2 5 4 ff0000
-1 5 4 ff0000
-6 6 4 ff0000
-5 6 4 ff0000
-4 6 4 ff0000
-3 6 4 ff0000
-2 6 4 ff0000
-1 6 4 ff0000
-5 7 4 ff0000
-4 7 4 ff0000
-3 7 4 ff0000
-2 7 4 ff0000
-1 7 4 ff0000
-4 8 4 ff0000
-3 8 4 ff0000
-2 8 4 ff0000
-1 8 4 ff0000
-6 1 5 ff0000
-5 1 5 ff0000
-4 1 5 ff0000
-7 2 5 ff0000
-6 2 5 ff0000
-5 2 5 ff0000
-4 2 5 ff0000
-3 2 5 ff0000
-7 3 5 ff0000
-6 3 5 ff0000
-5 3 5 ff0000
-4 3 5 ff0000
-3 3 5 ff0000
-7 4 5 ff0000
-6 4 5 ff0000
-5 4 5 ff0000
-4 4 5 ff0000
-3 4 5 ff0000
-2 4 5 ff0000
-7 5 5 ff0000
-6 5 5 ff0000
-5 5 5 ff0000
-4 5 5 ff0000
-3 5 5 ff0000
-2 5 5 ff0000
-1 5 5 ff0000
-6 6 5 ff0000
-5 6 5 ff0000
-4 6 5 ff0000
-3 6 5 ff0000
-2 6 5 ff0000
-1 6 5 ff0000
-5 7 5 ff0000
-4 7 5 ff0000
-3 7 5 ff0000
-2 7 5 ff0000
-1 7 5 ff0000
-4 8 5 ff0000
-3 8 5 ff0000
-2 8 5 ff0000
-1 8 5 ff0000
-6 2 6 ff4700
-5 2 6 ff4700
-4 2 6 ff4700
-6 3 6 ff4700
-5 3 6 ff4700
-4 3 6 ff4700
-6 4 6 ff4700
-5 4 6 ff4700
-4 4 6 ff4700
-3 4 6 ff4700
-6 5 6 ff4700
-5 5 6 ff4700
-4 5 6 ff4700
-3 5 6 ff4700
-2 5 6 ff4700
-5 6 6 ff4700
-4 6 6 ff4700
-3 6 6 ff4700
-2 6 6 ff4700
-1 6 6 ff4700
-4 7 6 ff4700
-3 7 6 ff4700
-2 7 6 ff4700
-1 7 6 ff4700
1 0 2 ff4700
2 0 2 ff4700
3 0 2 ff4700
4 0 2 ff4700
2 1 2 ff4700
3 1 2 ff4700
4 1 2 ff4700
5 1 2 ff4700
3 2 2 ff4700
4 2 2 ff4700
5 2 2 ff4700
3 3 2 ff4700
4 3 2 ff4700
5 3 2 ff4700
2 4 2 ff4700
3 4 2 ff4700
4 4 2 ff4700
5 4 2 ff4700
1 5 2 ff4700
2 5 2 ff4700
3 5 2 ff4700
4 5 2 ff4700
5 5 2 ff4700
0 6 2 ff4700
1 6 2 ff4700
2 6 2 ff4700
3 6 2 ff4700
4 6 2 ff4700
0 7 2 ff4700
1 7 2 ff4700
2 7 2 ff4700
3 7 2 ff4700
0 0 3 ff0000
1 0 3 ff0000
2 0 3 ff0000
3 0 3 ff0000
4 0 3 ff0000
5 0 3 ff0000
1 1 3 ff0000
2 1 3 ff0000
3 1 3 ff0000
4 1 3 ff0000
5 1 3 ff0000
6 1 3 ff0000
2 2 3 ff0000
3 2 3 ff0000
4 2 3 ff0000
5 2 3 ff0000
6 2 3 ff0000
2 3 3 ff0000
3 3 3 ff0000
4 3 3 ff0000
5 3 3 ff0000
6 3 3 ff0000
1 4 3 ff0000
2 4 3 ff0000
3 4 3 ff0000
4 4 3 ff0000
5 4 3 ff0000
6 4 3 ff0000
0 5 3 ff0000
1 5 3 ff0000
2 5 3 ff0000
3 5 3 ff0000
4 5 3 ff0000
5 5 3 ff0000
6 5 3 ff0000
0 6 3 ff0000
1 6 3 ff0000
2 6 3 ff0000
3 6 3 ff0000
4 6 3 ff0000
5 6 3 ff0000
0 7 3 ff0000
1 7 3 ff0000
2 7 3 ff0000
3 7 3 ff0000
4 7 3 ff0000
0 8 3 ff0000
1 8 3 ff0000
2 8 3 ff0000
3 8 3 ff0000
0 0 4 ff0000
1 0 4 ff0000
2 0 4 ff0000
3 0 4 ff0000
4 0 4 ff0000
5 0 4 ff0000
1 1 4 ff0000
2 1 4 ff0000
3 1 4 ff0000
4 1 4 ff0000
5 1 4 ff0000
6 1 4 ff0000
2 2 4 ff0000
3 2 4 ff0000
4 2 4 ff0000
5 2 4 ff0000
6 2 4 ff0000
2 3 4 ff0000
3 3 4 ff0000
4 3 4 ff0000
5 3 4 ff0000
6 3 4 ff0000
1 4 4 ff0000
2 4 4 ff0000
3 4 4 ff0000
4 4 4 ff0000
5 4 4 ff0000
6 4 4 ff0000
0 5 4 ff0000
1 5 4 ff0000
2 5 4 ff0000
3 5 4 ff0000
4 5 4 ff0000
5 5 4 ff0000
6 5 4 ff0000
0 6 4 ff0000
1 6 4 ff0000
2 6 4 ff0000
3 6 4 ff0000
4 6 4 ff0000
5 6 4 ff0000
0 7 4 ff0000
1 7 4 ff0000
2 7 4 ff0000
3 7 4 ff0000
4 7 4 ff0000
0 8 4 ff0000
1 8 4 ff0000
2 8 4 ff0000
3 8 4 ff0000
0 0 5 ff0000
1 0 5 ff0000
2 0 5 ff0000
3 0 5 ff0000
4 0 5 ff0000
5 0 5 ff0000
1 1 5 ff0000
2 1 5 ff0000
3 1 5 ff0000
4 1 5 ff0000
5 1 5 ff0000
6 1 5 ff0000
2 2 5 ff0000
3 2 5 ff0000
4 2 5 ff0000
5 2 5 ff0000
6 2 5 ff0000
2 3 5 ff0000
3 3 5 ff0000
4 3 5 ff0000
5 3 5 ff0000
6 3 5 ff0000
1 4 5 ff0000
2 4 5 ff0000
3 4 5 ff0000
4 4 5 ff0000
5 4 5 ff0000
6 4 5 ff0000
0 5 5 ff0000
1 5 5 ff0000
2 5 5 ff0000
3 5 5 ff0000
4 5 5 ff0000
5 5 5 ff0000
6 5 5 ff0000
0 6 5 ff0000
1 6 5 ff0000
2 6 5 ff0000
3 6 5 ff0000
4 6 5 ff0000
5 6 5 ff0000
0 7 5 ff0000
1 7 5 ff0000
2 7 5 ff0000
3 7 5 ff0000
4 7 5 ff0000
0 8 5 ff0000
1 8 5 ff0000
2 8 5 ff0000
3 8 5 ff0000
1 0 6 ff4700
2 0 6 ff4700
3 0 6 ff4700
4 0 6 ff4700
2 1 6 ff4700
3 1 6 ff4700
4 1 6 ff4700
5 1 6 ff4700
3 2 6 ff4700
4 2 6 ff4700
5 2 6 ff4700
3 3 6 ff4700
4 3 6 ff4700
5 3 6 ff4700
2 4 6 ff4700
3 4 6 ff4700
4 4 6 ff4700
5 4 6 ff4700
1 5 6 ff4700
2 5 6 ff4700
3 5 6 ff4700
4 5 6 ff4700
5 5 6 ff4700
0 6 6 ff4700
1 6 6 ff4700
2 6 6 ff4700
3 6 6 ff4700
4 6 6 ff4700
0 7 6 ff4700
1 7 6 ff4700
2 7 6 ff4700
3 7 6 ff4700
